Workbook
Name Adj_Market_Cap: [9]MASK!$B$18
Name COLUMN_CURR_YEAR: [9]MASK!$EV$10
Name COLUMN_FISCAL_YEAR: [9]MASK!$EV$16
Name COLUMN_LAST_QUARTER: [9]MASK!$EV$11
Name Curr_EV: [9]MASK!$B$22
Name Curr_MCap: [9]MASK!$B$17
Name Current_Year: [9]MASK!$EV$9
Name Data: #REF!
Name Dvd_Paid: [9]MASK!$D$15
Name Ext_DVD_Short_Term: [9]MASK!$B$19
Name Fair_Eq_Tdy_KeHigh: [9]MASK!$B$466
Name Fair_Eq_Tdy_KeLow: [9]MASK!$B$463
Name Fiscal_Month: [9]MASK!$EV$15
Name Fiscal_Year: [9]MASK!$EV$8
Name G_Perp_Nominal: [9]MASK!$B$27
Name G_Perp_Real: [9]MASK!$B$25
Name Hoje: [9]MASK!$EV$13
Name Ke_High: [9]MASK!$B$29
Name Ke_Low: [9]MASK!$B$28
Name LAST_QUARTER: [9]MASK!$B$6
Name LAST_QUARTER_DATE: [9]MASK!$EV$18
Name LT_Inflation: [9]MASK!$B$26
Name Modo_Operacao: [9]MASK!$C$671
Name Net_revenues: #REF!
Name NPV_FiscalBenfit: [9]MASK!$B$20
Name NPV_NOMINAL: [9]MASK!$B$38
Name Perp_Year: [9]MASK!$B$24
Name ProRata_Fiscal_Year: [9]MASK!$EV$12
Name RANGE_SCENARIOS: [9]MASK!$GD$16:$GN$16
Name REC: #REF!
Name ROW_SELECTION: [9]MASK!$FZ$16
Name SCENARIOS_CHOICE: [9]MASK!$AW$65
Name SharesOut_Diluted: [9]MASK!$B$9
Name Target_Ke_High: [9]MASK!$Q$6
Name Target_Ke_Low: [9]MASK!$Q$5
Name Valuation_Metric: [9]MASK!$C$672

Sheet DCF
C3: #VALUE! | F3: Premissas | I3: DCF Target
I4: Ke | J4: R$/Ação | K4: Upside
C5: # Ações (mil) | D5: =153000 -> 153000 | F5: Ke | G5: 0.14 | I5: =I6-1% -> 0.13 | J5: =SUM(E28:O28)/D5*1000 -> 22.037683 | K5: =J5/D6-1 -> 0.4682001
C6: Preço/Ação | D6: {=_FV(C3,"Preço")} -> 15.01 | F6: g | G6: 0.05 | I6: =G5 -> 0.14 | J6: =(SUM(E25:O25)/D5)*1000 -> 19.141142 | K6: =J6/D6-1 -> 0.27522596
C7: Market Cap (mil) | D7: =D5*D6 -> 2296530 | I7: =I6+1% -> 0.15 | J7: =SUM(E27:O27)/D5*1000 -> 16.856774 | K7: =J7/D6-1 -> 0.12303626
C10: DCF (R$ Mn) | E10: 2026 | F10: =E10+1 -> 2027 | G10: =F10+1 -> 2028 | H10: =G10+1 -> 2029 | I10: =H10+1 -> 2030 | J10: =I10+1 -> 2031 | K10: =J10+1 -> 2032 | L10: =K10+1 -> 2033 | M10: =L10+1 -> 2034 | N10: =M10+1 -> 2035 | O10: Perp
C12: Data | E12: 46387 | F12: =EOMONTH(E12,12) -> 46752 | G12: =EOMONTH(F12,12) -> 47118 | H12: =EOMONTH(G12,12) -> 47483 | I12: =EOMONTH(H12,12) -> 47848 | J12: =EOMONTH(I12,12) -> 48213 | K12: =EOMONTH(J12,12) -> 48579 | L12: =EOMONTH(K12,12) -> 48944 | M12: =EOMONTH(L12,12) -> 49309 | ... O12: =EOMONTH(N12,12) -> 50040
C13: Período | E13: =+(E12-TODAY())/365 -> 0.49315068 | F13: =+(F12-TODAY())/365 -> 1.4931507 | G13: =+(G12-TODAY())/365 -> 2.4958904 | H13: =+(H12-TODAY())/365 -> 3.4958904 | I13: =+(I12-TODAY())/365 -> 4.4958904 | J13: =+(J12-TODAY())/365 -> 5.4958904 | K13: =+(K12-TODAY())/365 -> 6.4986301 | L13: =+(L12-TODAY())/365 -> 7.4986301 | ... O13: =+(O12-TODAY())/365 -> 10.50137
C15: EBITDA | E15: =Modelo!AK91 -> 297.94183 | F15: =Modelo!AL91 -> 353.14299 | G15: =Modelo!AM91 -> 416.63398 | H15: =Modelo!AN91 -> 487.75857 | I15: =Modelo!AO91 -> 567.20042 | J15: =Modelo!AP91 -> 655.69482 | K15: =Modelo!AQ91 -> 754.03214 | L15: =Modelo!AR91 -> 863.06161 | ... N15: =Modelo!AT91 -> 1116.912 | O15: =N15*(1+$G$6) -> 1172.7576
C16: (-) Resultado financeiro | E16: =Modelo!AK92 -> -39.761249 | F16: =Modelo!AL92 -> -46.131487 | G16: =Modelo!AM92 -> -52.682328 | H16: =Modelo!AN92 -> -57.280853 | I16: =Modelo!AO92 -> -61.873279 | J16: =Modelo!AP92 -> -66.429598 | K16: =Modelo!AQ92 -> -70.915934 | L16: =Modelo!AR92 -> -75.294189 | ... N16: =Modelo!AT92 -> -83.550594 | O16: =N16*(1+$G$6) -> -87.728124
C17: (-) IR/CS | E17: =Modelo!AK93 -> -35.576112 | F17: =Modelo!AL93 -> -51.966339 | G17: =Modelo!AM93 -> -36.359147 | H17: =Modelo!AN93 -> -44.856219 | I17: =Modelo!AO93 -> -54.910463 | J17: =Modelo!AP93 -> -66.86585 | K17: =Modelo!AQ93 -> -80.898469 | L17: =Modelo!AR93 -> -97.203272 | ... N17: =Modelo!AT93 -> -137.50643 | O17: =N17*(1+$G$6) -> -144.38175
C18: (-) ∆ WKC | E18: =Modelo!AK94 -> -48.5517 | F18: =Modelo!AL94 -> -73.381562 | G18: =Modelo!AM94 -> -81.537316 | H18: =Modelo!AN94 -> -87.817429 | I18: =Modelo!AO94 -> -94.499064 | J18: =Modelo!AP94 -> -101.60558 | K18: =Modelo!AQ94 -> -109.16162 | L18: =Modelo!AR94 -> -117.1932 | ... N18: =Modelo!AT94 -> -134.79413 | O18: =N18*(1+$G$6) -> -141.53384
C19: (-) Adição Imobilizado | E19: =Modelo!AK95 -> -41.929642 | F19: =Modelo!AL95 -> -47.188925 | G19: =Modelo!AM95 -> -53.010723 | H19: =Modelo!AN95 -> -59.27071 | I19: =Modelo!AO95 -> -65.996638 | J19: =Modelo!AP95 -> -73.217866 | K19: =Modelo!AQ95 -> -80.965449 | L19: =Modelo!AR95 -> -89.272229 | ... N19: =Modelo!AT95 -> -107.70428 | O19: =N19*(1+$G$6) -> -113.08949
C20: (-) Adição Intangível | E20: =Modelo!AK96 -> -13.000867 | F20: =Modelo!AL96 -> -14.834889 | G20: =Modelo!AM96 -> -16.872748 | H20: =Modelo!AN96 -> -19.067565 | I20: =Modelo!AO96 -> -21.429376 | J20: =Modelo!AP96 -> -23.9688 | K20: =Modelo!AQ96 -> -26.697072 | L20: =Modelo!AR96 -> -29.626076 | ... N20: =Modelo!AT96 -> -36.137287 | O20: =N20*(1+$G$6) -> -37.944152
C21: (-) Depreciação Direito de Uso | E21: =Modelo!AK97 -> -22.246674 | F21: =Modelo!AL97 -> -25.861758 | G21: =Modelo!AM97 -> -29.782735 | H21: =Modelo!AN97 -> -34.031154 | I21: =Modelo!AO97 -> -38.629959 | J21: =Modelo!AP97 -> -43.603566 | K21: =Modelo!AQ97 -> -48.977959 | L21: =Modelo!AR97 -> -54.780782 | ... N21: =Modelo!AT97 -> -67.791218 | O21: =N21*(1+$G$6) -> -71.180779
C22: (+/-) Δ Dívida | E22: =Modelo!AK128-Modelo!AF128 -> 35.636814 | F22: =Modelo!AL128-Modelo!AK128 -> 18.873 | G22: =Modelo!AM128-Modelo!AL128 -> 0 | H22: =Modelo!AN128-Modelo!AM128 -> 0 | I22: =Modelo!AO128-Modelo!AN128 -> 0 | J22: =Modelo!AP128-Modelo!AO128 -> 0 | K22: =Modelo!AQ128-Modelo!AP128 -> 0 | L22: =Modelo!AR128-Modelo!AQ128 -> 0 | M22: =Modelo!AS128-Modelo!AR128 -> 0 | N22: =Modelo!AT128-Modelo!AS128 -> 0 | O22: =N22*(1+$G$6) -> 0
C23: FCFE | E23: =SUM(E15:E22) -> 132.5124 | F23: =SUM(F15:F22) -> 112.65103 | G23: =SUM(G15:G22) -> 146.38899 | H23: =SUM(H15:H22) -> 185.43464 | I23: =SUM(I15:I22) -> 229.86164 | J23: =SUM(J15:J22) -> 280.00356 | K23: =SUM(K15:K22) -> 336.41563 | L23: =SUM(L15:L22) -> 399.69186 | ... O23: =SUM(O15:O22) -> 576.89944
C25: FCFE Valor Presente | E25: =E23/(1+$G$5)^E13 -> 124.22067 | F25: =F23/(1+$G$5)^F13 -> 92.633406 | G25: =G23/(1+$G$5)^G13 -> 105.55532 | H25: =H23/(1+$G$5)^H13 -> 117.28912 | I25: =I23/(1+$G$5)^I13 -> 127.53475 | J25: =J23/(1+$G$5)^J13 -> 136.27642 | K25: =K23/(1+$G$5)^K13 -> 143.57294 | L25: =L23/(1+$G$5)^L13 -> 149.62938 | ... N25: =N23/(1+$G$5)^N13 -> 158.26784 | O25: =(O23/(G5-G6))/((1+G5)^O13) -> 1619.1188
C27: FCFE Valor Presente (Ke+1%) | E27: =E23/(1+$I$7)^E13 -> 123.6868 | F27: =F23/(1+$I$7)^F13 -> 91.433244 | G27: =G23/(1+$I$7)^G13 -> 103.27929 | H27: =H23/(1+$I$7)^H13 -> 113.76217 | I27: =I23/(1+$I$7)^I13 -> 122.62405 | J27: =J23/(1+$I$7)^J13 -> 129.88975 | K27: =K23/(1+$I$7)^K13 -> 135.65111 | L27: =L23/(1+$I$7)^L13 -> 140.14405 | ... N27: =N23/(1+$I$7)^N13 -> 145.66811 | O27: =(O23/(I7-G6))/((1+I7)^O13) -> 1329.504
C28: FCFE Valor Presente (Ke-1%) | E28: =E23/(1+$I$5)^E13 -> 124.76158 | F28: =F23/(1+$I$5)^F13 -> 93.860106 | G28: =G23/(1+$I$5)^G13 -> 107.90223 | H28: =H23/(1+$I$5)^H13 -> 120.95796 | I28: =I23/(1+$I$5)^I13 -> 132.688 | J28: =J23/(1+$I$5)^J13 -> 143.03761 | K28: =K23/(1+$I$5)^K13 -> 152.0334 | L28: =L23/(1+$I$5)^L13 -> 159.84891 | ... N28: =N23/(1+$I$5)^N13 -> 172.08314 | O28: =(O23/(I5-G6))/((1+I5)^O13) -> 1998.0841

Sheet Modelo
B2: TFCO | R$ MM | C2: 1T20 | D2: 2T20 | E2: 3T20 | F2: 4T20 | G2: 2020 | H2: 1T21 | I2: 2T21 | J2: 3T21 | K2: 4T21 | L2: 2021 | M2: 1T22 | N2: 2T22 | O2: 3T22 | P2: 4T22 | Q2: 2022 | R2: 1T23 | S2: 2T23 | T2: 3T23 | U2: 4T23 | V2: 2023 | W2: 1T24 | X2: 2T24 | Y2: 3T24 | Z2: 4T24 | AA2: 2024 | AB2: 1T25 | AC2: 2T25 | AD2: 3T25 | AE2: 4T25 | AF2: 2025 | AG2: 1T26 | AH2: 2T26 | AI2: 3T26 | AJ2: 4T26 | AK2: 2026 | AL2: 2027 | AM2: 2028 | AN2: 2029 | AO2: 2030 | AP2: 2031 | AQ2: 2032 | AR2: 2033 | AS2: 2034 | AT2: 2035 | AU2: x
AU3: x
A4: * | B4: 1 - Macro | AU4: x
AU5: x
B6: Selic Média | C6: 0.04177934 | D6: 0.03070842 | E6: 0.019402529 | F6: 0.019913713 | G6: =AVERAGE(C6:F6) -> 0.027951 | H6: 0.02 | I6: 0.035 | J6: 0.05 | K6: 0.0775 | L6: =AVERAGE(H6:K6) -> 0.045625 | M6: 0.105 | N6: 0.125 | O6: 0.136 | P6: 0.1375 | Q6: =AVERAGE(M6:P6) -> 0.125875 | R6: 0.1375 | S6: 0.1375 | T6: 0.1325 | U6: 0.1175 | V6: =AVERAGE(R6:U6) -> 0.13125 | W6: 0.111 | X6: 0.106 | Y6: 0.1058 | Z6: 0.114 | AA6: =AVERAGE(W6:Z6) -> 0.1092 | AB6: 0.136 | AC6: 0.147 | AD6: 0.15 | AE6: 0.15 | AF6: =AVERAGE(AB6:AE6) -> 0.14575 | AG6: 0.1483 | AH6: 0.138 | AI6: 0.13 | AJ6: 0.123 | AK6: =AVERAGE(AG6:AJ6) -> 0.134825 | AL6: 0.114 | AM6: 0.1 | AN6: 0.1 | AO6: 0.1 | AP6: 0.1 | AQ6: 0.1 | AR6: 0.1 | AS6: 0.1 | AT6: 0.1 | AU6: x
AU7: x
A8: * | B8: 2 - DRE | AU8: x
AU9: x
B10: Receita bruta | C10: =C167 -> 79.399 | D10: =D167 -> 32.289 | E10: =E167 -> 91.496 | F10: =F167 -> 165.739 | G10: =SUM(C10:F10) -> 368.923 | H10: =H167 -> 90.209 | I10: =I167 -> 129.463 | J10: =J167 -> 169.233 | K10: =K167 -> 208.349 | L10: =SUM(H10:K10) -> 597.254 | M10: =M167 -> 154.327 | N10: =N167 -> 177.559 | O10: =O167 -> 186.314 | P10: =P167 -> 257.899 | Q10: =SUM(M10:P10) -> 776.099 | R10: =R167 -> 195.898 | S10: =S167 -> 208.92 | T10: =T167 -> 221.746 | U10: =U167 -> 303.121 | V10: =SUM(R10:U10) -> 929.685 | W10: =W167 -> 223.426 | X10: =X167 -> 258.196 | Y10: =Y167 -> 269.476 | Z10: =Z167 -> 368.172 | AA10: =SUM(W10:Z10) -> 1119.27 | AB10: =AB167 -> 288.208 | AC10: =AC167 -> 324.73 | AD10: =AD167 -> 360.077 | AE10: =AE167 -> 437.099 | AF10: =SUM(AB10:AE10) -> 1410.114 | AG10: =AG167 -> 344.944 | AH10: =AH167 -> 357.84012 | AI10: =AI167 -> 377.82457 | AJ10: =AJ167 -> 504.64758 | AK10: =SUM(AG10:AJ10) -> 1585.2563 | AL10: =AL167 -> 1808.8871 | AM10: =AM167 -> 2057.3727 | AN10: =AN167 -> 2324.997 | AO10: =AO167 -> 2612.9836 | AP10: =AP167 -> 2922.6273 | AQ10: =AQ167 -> 3255.2982 | AR10: =AR167 -> 3612.4454 | AS10: =AS167 -> 3995.6015 | AT10: =AT167 -> 4406.3877 | AU10: x
B11: % yoy | H11: =H10/C10-1 -> 0.13614781 | I11: =I10/D10-1 -> 3.0095079 | J11: =J10/E10-1 -> 0.84962184 | K11: =K10/F10-1 -> 0.25709097 | L11: =L10/SUM(C10:F10)-1 -> 0.61891235 | M11: =M10/H10-1 -> 0.71077165 | N11: =N10/I10-1 -> 0.37150383 | O11: =O10/J10-1 -> 0.10093185 | P11: =P10/K10-1 -> 0.23782212 | Q11: =Q10/SUM(H10:K10)-1 -> 0.29944546 | R11: =R10/M10-1 -> 0.26936959 | S11: =S10/N10-1 -> 0.17662298 | T11: =T10/O10-1 -> 0.19017358 | U11: =U10/P10-1 -> 0.17534771 | V11: =V10/SUM(M10:P10)-1 -> 0.19789486 | W11: =W10/R10-1 -> 0.14052211 | X11: =X10/S10-1 -> 0.23586062 | Y11: =Y10/T10-1 -> 0.21524627 | Z11: =Z10/U10-1 -> 0.21460407 | AA11: =AA10/SUM(R10:U10)-1 -> 0.20392391 | AB11: =AB10/W10-1 -> 0.28994835 | AC11: =AC10/X10-1 -> 0.25768796 | AD11: =AD10/Y10-1 -> 0.33621176 | AE11: =AE10/Z10-1 -> 0.18721413 | AF11: =AF10/SUM(W10:Z10)-1 -> 0.25985151 | AG11: =AG10/AB10-1 -> 0.19685782 | AH11: =AH10/AC10-1 -> 0.101962 | AI11: =AI10/AD10-1 -> 0.049288251 | AJ11: =AJ10/AE10-1 -> 0.15453839 | AK11: =AK10/SUM(AB10:AE10)-1 -> 0.12420433 | AL11: =AL10/AK10-1 -> 0.14106922 | AM11: =AM10/AL10-1 -> 0.13736931 | AN11: =AN10/AM10-1 -> 0.1300806 | AO11: =AO10/AN10-1 -> 0.12386537 | AP11: =AP10/AO10-1 -> 0.118502 | AQ11: =AQ10/AP10-1 -> 0.11382596 | AR11: =AR10/AQ10-1 -> 0.10971257 | AS11: =AS10/AR10-1 -> 0.1060656 | AT11: =AT10/AS10-1 -> 0.10280958 | AU11: x
AU12: x
B13: (-) Deduções | C13: =C16-C10 -> -23.265 | D13: =D16-D10 -> -8.856 | E13: =E16-E10 -> -25.228 | F13: =F16-F10 -> -44.25447 | G13: =SUM(C13:F13) -> -101.60347 | H13: =H16-H10 -> -26.496 | I13: =I16-I10 -> -35.024 | J13: =J16-J10 -> -44.451986 | K13: =K16-K10 -> -56.690169 | L13: =SUM(H13:K13) -> -162.66216 | M13: =M16-M10 -> -41.803 | N13: =N16-N10 -> -46.116 | O13: =O16-O10 -> -48.167 | P13: =P16-P10 -> -72.587 | Q13: =SUM(M13:P13) -> -208.673 | R13: =R16-R10 -> -54.208 | S13: =S16-S10 -> -53.144612 | T13: =T16-T10 -> -57.468275 | U13: =U16-U10 -> -81.174 | V13: =SUM(R13:U13) -> -245.99489 | W13: =W16-W10 -> -61.295 | X13: =X16-X10 -> -66.194 | Y13: =Y16-Y10 -> -65.141 | Z13: =Z16-Z10 -> -94.881 | AA13: =SUM(W13:Z13) -> -287.511 | AB13: =AB16-AB10 -> -75.422 | AC13: =AC16-AC10 -> -82.639 | AD13: =AD16-AD10 -> -91.548 | AE13: =AE16-AE10 -> -113.993 | AF13: =SUM(AB13:AE13) -> -363.602 | AG13: =AG16-AG10 -> -93.786 | AH13: =AH16-AH10 -> -97.292295 | AI13: =AI16-AI10 -> -102.72582 | AJ13: =AJ16-AJ10 -> -137.20742 | AK13: =SUM(AG13:AJ13) -> -431.01154 | AL13: =AL16-AL10 -> -491.814 | AM13: =AM16-AM10 -> -559.37415 | AN13: =AN16-AN10 -> -632.13787 | AO13: =AO16-AO10 -> -710.43786 | AP13: =AP16-AP10 -> -794.62617 | AQ13: =AQ16-AQ10 -> -885.07525 | AR13: =AR16-AR10 -> -982.17914 | AS13: =AS16-AS10 -> -1086.3546 | AT13: =AT16-AT10 -> -1198.0422 | AU13: x
B14: % RB | C14: =C13/C10 -> -0.29301377 | D14: =D13/D10 -> -0.27427297 | E14: =E13/E10 -> -0.2757279 | F14: =F13/F10 -> -0.26701302 | G14: =G13/G10 -> -0.27540563 | H14: =H13/H10 -> -0.29371792 | I14: =I13/I10 -> -0.27053289 | J14: =J13/J10 -> -0.26266737 | ... AT14: =AT13/AT10 -> -0.27188761 | AU14: x
AU15: x
B16: Receita líquida | C16: 56.134 | D16: 23.433 | E16: 66.268 | F16: 121.48453 | G16: =SUM(C16:F16) -> 267.31953 | H16: 63.713 | I16: 94.439 | J16: 124.78101 | K16: 151.65883 | L16: =SUM(H16:K16) -> 434.59184 | M16: 112.524 | N16: 131.443 | O16: 138.147 | P16: 185.312 | Q16: =SUM(M16:P16) -> 567.426 | R16: 141.69 | S16: 155.77539 | T16: 164.27772 | U16: 221.947 | V16: =SUM(R16:U16) -> 683.69011 | W16: 162.131 | X16: 192.002 | Y16: 204.335 | Z16: 273.291 | AA16: =SUM(W16:Z16) -> 831.759 | AB16: 212.786 | AC16: 242.091 | AD16: 268.529 | AE16: 323.106 | AF16: =SUM(AB16:AE16) -> 1046.512 | AG16: 251.158 | AH16: =AH199 -> 260.54783 | AI16: =AI199 -> 275.09875 | AJ16: =AJ199 -> 367.44015 | AK16: =SUM(AG16:AJ16) -> 1154.2447 | AL16: =AL199 -> 1317.0731 | AM16: =AM199 -> 1497.9986 | AN16: =AN199 -> 1692.8591 | AO16: =AO199 -> 1902.5457 | AP16: =AP199 -> 2128.0012 | AQ16: =AQ199 -> 2370.223 | AR16: =AR199 -> 2630.2662 | AS16: =AS199 -> 2909.247 | AT16: =AT199 -> 3208.3455 | AU16: x
B17: % yoy | H17: =H16/C16-1 -> 0.13501621 | I17: =I16/D16-1 -> 3.0301711 | J17: =J16/E16-1 -> 0.8829754 | K17: =K16/F16-1 -> 0.24837978 | L17: =L16/SUM(C16:F16)-1 -> 0.62573922 | M17: =M16/H16-1 -> 0.76610739 | N17: =N16/I16-1 -> 0.39182965 | O17: =O16/J16-1 -> 0.10711555 | P17: =P16/K16-1 -> 0.22190049 | Q17: =Q16/SUM(H16:K16)-1 -> 0.30565267 | R17: =R16/M16-1 -> 0.25919804 | S17: =S16/N16-1 -> 0.18511741 | T17: =T16/O16-1 -> 0.18915159 | U17: =U16/P16-1 -> 0.19769362 | V17: =V16/SUM(M16:P16)-1 -> 0.2048974 | W17: =W16/R16-1 -> 0.14426565 | X17: =X16/S16-1 -> 0.23255671 | Y17: =Y16/T16-1 -> 0.24383875 | Z17: =Z16/U16-1 -> 0.23133451 | AA17: =AA16/SUM(R16:U16)-1 -> 0.2165731 | AB17: =AB16/W16-1 -> 0.31243254 | AC17: =AC16/X16-1 -> 0.26087749 | AD17: =AD16/Y16-1 -> 0.31416057 | AE17: =AE16/Z16-1 -> 0.18227823 | AF17: =AF16/SUM(W16:Z16)-1 -> 0.25819138 | AG17: =AG16/AB16-1 -> 0.18033141 | AH17: =AH16/AC16-1 -> 0.076239205 | AI17: =AI16/AD16-1 -> 0.024465689 | AJ17: =AJ16/AE16-1 -> 0.13721241 | AK17: =AK16/SUM(AB16:AE16)-1 -> 0.10294457 | AL17: =AL16/AK16-1 -> 0.14106922 | AM17: =AM16/AL16-1 -> 0.13736931 | AN17: =AN16/AM16-1 -> 0.1300806 | AO17: =AO16/AN16-1 -> 0.12386537 | AP17: =AP16/AO16-1 -> 0.118502 | AQ17: =AQ16/AP16-1 -> 0.11382596 | AR17: =AR16/AQ16-1 -> 0.10971257 | AS17: =AS16/AR16-1 -> 0.1060656 | AT17: =AT16/AS16-1 -> 0.10280958 | AU17: x
AU18: x
B19: (-) Custos | C19: =C519 -> -26.721 | D19: =D519 -> -9.689 | E19: =E519 -> -27.264 | F19: =F519 -> -47.755108 | G19: =SUM(C19:F19) -> -111.42911 | H19: =H519 -> -22.91 | I19: =I519 -> -38.13169 | J19: =J519 -> -54.499536 | K19: =K519 -> -59.000391 | L19: =SUM(H19:K19) -> -174.54162 | M19: =M519 -> -44.85709 | N19: =N519 -> -60.145 | O19: =O519 -> -58.781319 | P19: =P519 -> -76.366 | Q19: =SUM(M19:P19) -> -240.14941 | R19: =R519 -> -57.854952 | S19: =S519 -> -66.332 | T19: =T519 -> -69.142 | U19: =U519 -> -93.332376 | V19: =SUM(R19:U19) -> -286.66133 | W19: =W519 -> -65.910136 | X19: =X519 -> -84.517 | Y19: =Y519 -> -90.405 | Z19: =Z519 -> -118.127 | AA19: =SUM(W19:Z19) -> -358.95914 | AB19: =AB519 -> -82.463219 | AC19: =AC519 -> -102.751 | AD19: =AD519 -> -126.1176 | AE19: =AE519 -> -131.973 | AF19: =SUM(AB19:AE19) -> -443.30482 | AG19: =AG519 -> -100.4 | AH19: =AH21-AH16 -> -103.5022 | AI19: =AI21-AI16 -> -108.59478 | AJ19: =AJ21-AJ16 -> -144.1278 | AK19: =SUM(AG19:AJ19) -> -456.62478 | AL19: =AL21-AL16 -> -507.86975 | AM19: =AM21-AM16 -> -562.65548 | AN19: =AN21-AN16 -> -618.91745 | AO19: =AO21-AO16 -> -676.55443 | AP19: =AP21-AP16 -> -735.44747 | AQ19: =AQ21-AQ16 -> -795.45825 | AR19: =AR21-AR16 -> -856.42736 | AS19: =AS21-AS16 -> -918.17237 | AT19: =AT21-AT16 -> -980.48584 | AU19: x
AU20: x
B21: Lucro bruto | C21: =C16+C19 -> 29.413 | D21: =D16+D19 -> 13.744 | E21: =E16+E19 -> 39.004 | F21: =F16+F19 -> 73.729421 | G21: =SUM(C21:F21) -> 155.89042 | H21: =H16+H19 -> 40.803 | I21: =I16+I19 -> 56.30731 | J21: =J16+J19 -> 70.281478 | K21: =K16+K19 -> 92.65844 | L21: =SUM(H21:K21) -> 260.05023 | M21: =M16+M19 -> 67.66691 | N21: =N16+N19 -> 71.298 | O21: =O16+O19 -> 79.365681 | P21: =P16+P19 -> 108.946 | Q21: =SUM(M21:P21) -> 327.27659 | R21: =R16+R19 -> 83.835048 | S21: =S16+S19 -> 89.443388 | T21: =T16+T19 -> 95.135725 | U21: =U16+U19 -> 128.61462 | V21: =SUM(R21:U21) -> 397.02878 | W21: =W16+W19 -> 96.220864 | X21: =X16+X19 -> 107.485 | Y21: =Y16+Y19 -> 113.93 | Z21: =Z16+Z19 -> 155.164 | AA21: =SUM(W21:Z21) -> 472.79986 | AB21: =AB16+AB19 -> 130.32278 | AC21: =AC16+AC19 -> 139.34 | AD21: =AD16+AD19 -> 142.4114 | AE21: =AE16+AE19 -> 191.133 | AF21: =SUM(AB21:AE21) -> 603.20718 | AG21: =AG16+AG19 -> 150.758 | AH21: =AH22*AH16 -> 157.04563 | AI21: =AI22*AI16 -> 166.50397 | AJ21: =AJ22*AJ16 -> 223.31235 | AK21: =SUM(AG21:AJ21) -> 697.61995 | AL21: =AL22*AL16 -> 809.20338 | AM21: =AM22*AM16 -> 935.34307 | AN21: =AN22*AN16 -> 1073.9417 | AO21: =AO22*AO16 -> 1225.9913 | AP21: =AP22*AP16 -> 1392.5537 | AQ21: =AQ22*AQ16 -> 1574.7647 | AR21: =AR22*AR16 -> 1773.8389 | AS21: =AS22*AS16 -> 1991.0746 | AT21: =AT22*AT16 -> 2227.8596 | AU21: x
B22: % margem bruta | C22: =C21/C16 -> 0.52397834 | D22: =D21/D16 -> 0.58652328 | E22: =E21/E16 -> 0.58857971 | F22: =F21/F16 -> 0.60690379 | G22: =G21/G16 -> 0.58316136 | H22: =H21/H16 -> 0.64041875 | I22: =I21/I16 -> 0.59622942 | J22: =J21/J16 -> 0.56323855 | ... AG22: =AG21/AG16 -> 0.60025163 | AH22: =AG22+0.25% -> 0.60275163 | AI22: =AH22+0.25% -> 0.60525163 | AJ22: =AI22+0.25% -> 0.60775163 | AK22: =AK21/AK16 -> 0.60439518 | AL22: =AK22+0.01 -> 0.61439518 | AM22: =AL22+0.01 -> 0.62439518 | AN22: =AM22+0.01 -> 0.63439518 | AO22: =AN22+0.01 -> 0.64439518 | AP22: =AO22+0.01 -> 0.65439518 | AQ22: =AP22+0.01 -> 0.66439518 | AR22: =AQ22+0.01 -> 0.67439518 | AS22: =AR22+0.01 -> 0.68439518 | AT22: =AS22+0.01 -> 0.69439518 | AU22: x
AU23: x
B24: (-) Despesas | C24: =C520 -> -24.898 | D24: =D520 -> -14.406 | E24: =E520 -> -25.67 | F24: =F520 -> -39.466934 | G24: =SUM(C24:F24) -> -104.44093 | H24: =H520 -> -29.113 | I24: =I520 -> -36.716265 | J24: =J520 -> -44.101064 | K24: =K520 -> -48.663341 | L24: =SUM(H24:K24) -> -158.59367 | M24: =M520 -> -38.097992 | N24: =N520 -> -42.380252 | O24: =O520 -> -45.374634 | P24: =P520 -> -61.495478 | Q24: =SUM(M24:P24) -> -187.34836 | R24: =R520 -> -46.006 | S24: =S520 -> -49.672 | T24: =T520 -> -53.848 | U24: =U520 -> -75.877 | V24: =SUM(R24:U24) -> -225.403 | W24: =W520 -> -55.115 | X24: =X520 -> -63.305 | Y24: =Y520 -> -69.697375 | Z24: =Z520 -> -92.196 | AA24: =SUM(W24:Z24) -> -280.31338 | AB24: =AB520 -> -72.225979 | AC24: =AC520 -> -80.662 | AD24: =AD520 -> -87.259747 | AE24: =AE520 -> -107.428 | AF24: =SUM(AB24:AE24) -> -347.57573 | AG24: =AG520 -> -86.444 | AH24: =AH25*AH16 -> -89.675807 | AI24: =AI25*AI16 -> -94.683968 | AJ24: =AJ25*AJ16 -> -126.46619 | AK24: =SUM(AG24:AJ24) -> -397.26997 | AL24: =AL25*AL16 -> -453.31253 | AM24: =AM25*AM16 -> -515.58376 | AN24: =AN25*AN16 -> -582.65121 | AO24: =AO25*AO16 -> -654.82151 | AP24: =AP25*AP16 -> -732.41917 | AQ24: =AQ25*AQ16 -> -815.78749 | AR24: =AR25*AR16 -> -905.28963 | AS24: =AS25*AS16 -> -1001.3097 | AT24: =AT25*AT16 -> -1104.254 | AU24: x
B25: % RL | C25: =C24/C$16 -> -0.4435458 | D25: =D24/D$16 -> -0.61477404 | E25: =E24/E$16 -> -0.38736645 | F25: =F24/F$16 -> -0.3248721 | G25: =G24/G16 -> -0.39069698 | H25: =H24/H$16 -> -0.45693971 | I25: =I24/I$16 -> -0.38878286 | J25: =J24/J$16 -> -0.35342768 | K25: =K24/K$16 -> -0.32087377 | L25: =L24/L16 -> -0.36492555 | M25: =M24/M$16 -> -0.33857659 | N25: =N24/N$16 -> -0.32242304 | O25: =O24/O$16 -> -0.32845182 | P25: =P24/P$16 -> -0.33184833 | Q25: =Q24/Q16 -> -0.33017231 | R25: =R24/R$16 -> -0.32469476 | S25: =S24/S$16 -> -0.31886937 | T25: =T24/T$16 -> -0.32778638 | U25: =U24/U$16 -> -0.34186991 | V25: =V24/V16 -> -0.32968591 | W25: =W24/W$16 -> -0.33994116 | X25: =X24/X$16 -> -0.32971011 | Y25: =Y24/Y$16 -> -0.34109367 | Z25: =Z24/Z$16 -> -0.33735469 | AA25: =AA24/AA16 -> -0.33701273 | AB25: =AB24/AB$16 -> -0.33943013 | AC25: =AC24/AC$16 -> -0.33318876 | AD25: =AD24/AD$16 -> -0.32495465 | AE25: =AE24/AE$16 -> -0.33248531 | AF25: =AF24/AF16 -> -0.3321278 | AG25: =AG24/AG$16 -> -0.34418175 | AH25: =AG25 -> -0.34418175 | AI25: =AH25 -> -0.34418175 | AJ25: =AI25 -> -0.34418175 | AK25: =AK24/AK16 -> -0.34418175 | AL25: =AK25 -> -0.34418175 | AM25: =AL25 -> -0.34418175 | AN25: =AM25 -> -0.34418175 | AO25: =AN25 -> -0.34418175 | AP25: =AO25 -> -0.34418175 | AQ25: =AP25 -> -0.34418175 | AR25: =AQ25 -> -0.34418175 | AS25: =AR25 -> -0.34418175 | AT25: =AS25 -> -0.34418175 | AU25: x
AU26: x
B27: (-) Outras receitas (despesas) | C27: -0.308 | D27: 1.727 | E27: -0.416 | F27: -0.91179633 | G27: =SUM(C27:F27) -> 0.09120367 | H27: -0.7 | I27: 0.565 | J27: 0.85291429 | K27: -0.29653536 | L27: =SUM(H27:K27) -> 0.42137893 | M27: 2.802877 | N27: -0.123 | O27: 0.248 | P27: 0.905 | Q27: =SUM(M27:P27) -> 3.832877 | R27: -0.05036613 | S27: 1.0992736 | T27: -0.00735135 | U27: 1.063 | V27: =SUM(R27:U27) -> 2.1045561 | W27: 0.30744589 | X27: -0.339 | Y27: 0.77443631 | Z27: 2.996074 | AA27: =SUM(W27:Z27) -> 3.7389562 | AB27: 0.48981088 | AC27: -0.38 | AD27: 1.721 | AE27: -8.049 | AF27: =SUM(AB27:AE27) -> -6.2181891 | AG27: -0.524 | AH27: =AH28*AH16 -> -0.54359033 | AI27: =AI28*AI16 -> -0.57394844 | AJ27: =AJ28*AJ16 -> -0.76660365 | AK27: =SUM(AG27:AJ27) -> -2.4081424 | AL27: =AL28*AL16 -> -2.7478572 | AM27: =AM28*AM16 -> -3.1253284 | AN27: =AN28*AN16 -> -3.531873 | AO27: =AO28*AO16 -> -3.9693498 | AP27: =AP28*AP16 -> -4.4397257 | AQ27: =AQ28*AQ16 -> -4.9450817 | AR27: =AR28*AR16 -> -5.4876193 | AS27: =AS28*AS16 -> -6.069667 | AT27: =AT28*AT16 -> -6.6936869 | AU27: x
B28: % RL | C28: =C27/C$16 -> -0.0054868707 | D28: =D27/D$16 -> 0.073699484 | E28: =E27/E$16 -> -0.0062775397 | F28: =F27/F$16 -> -0.0075054522 | G28: =G27/G16 -> 0.00034117848 | H28: =H27/H$16 -> -0.010986769 | I28: =I27/I$16 -> 0.0059826978 | J28: =J27/J$16 -> 0.006835289 | K28: =K27/K$16 -> -0.0019552792 | L28: =L27/L16 -> 0.00096959696 | M28: =M27/M$16 -> 0.024909148 | N28: =N27/N$16 -> -0.00093576683 | O28: =O27/O$16 -> 0.0017951892 | P28: =P27/P$16 -> 0.0048836557 | Q28: =Q27/Q16 -> 0.006754849 | R28: =R27/R$16 -> -0.00035546708 | S28: =S27/S$16 -> 0.007056786 | T28: =T27/T$16 -> -4.4749524e-05 | U28: =U27/U$16 -> 0.0047894317 | V28: =V27/V16 -> 0.003078231 | W28: =W27/W$16 -> 0.0018962807 | X28: =X27/X$16 -> -0.0017656066 | Y28: =Y27/Y$16 -> 0.0037900326 | Z28: =Z27/Z$16 -> 0.010962944 | AA28: =AA27/AA16 -> 0.0044952399 | AB28: =AB27/AB$16 -> 0.0023018943 | AC28: =AC27/AC$16 -> -0.0015696577 | AD28: =AD27/AD$16 -> 0.0064089912 | AE28: =AE27/AE$16 -> -0.024911329 | AF28: =AF27/AF16 -> -0.005941823 | AG28: =AG27/AG$16 -> -0.0020863361 | AH28: =AG28 -> -0.0020863361 | AI28: =AH28 -> -0.0020863361 | AJ28: =AI28 -> -0.0020863361 | AK28: =AK27/AK16 -> -0.0020863361 | AL28: =AK28 -> -0.0020863361 | AM28: =AL28 -> -0.0020863361 | AN28: =AM28 -> -0.0020863361 | AO28: =AN28 -> -0.0020863361 | AP28: =AO28 -> -0.0020863361 | AQ28: =AP28 -> -0.0020863361 | AR28: =AQ28 -> -0.0020863361 | AS28: =AR28 -> -0.0020863361 | AT28: =AS28 -> -0.0020863361 | AU28: x
AU29: x
B30: EBITDA | C30: =C21+C24+C27 -> 4.207 | D30: =D21+D24+D27 -> 1.065 | E30: =E21+E24+E27 -> 12.918 | F30: =F21+F24+F27 -> 33.350691 | G30: =SUM(C30:F30) -> 51.540691 | H30: =H21+H24+H27 -> 10.99 | I30: =I21+I24+I27 -> 20.156045 | J30: =J21+J24+J27 -> 27.033328 | K30: =K21+K24+K27 -> 43.698564 | L30: =SUM(H30:K30) -> 101.87794 | M30: =M21+M24+M27 -> 32.371795 | N30: =N21+N24+N27 -> 28.794748 | O30: =O21+O24+O27 -> 34.239047 | P30: =P21+P24+P27 -> 48.355522 | Q30: =SUM(M30:P30) -> 143.76111 | R30: =R21+R24+R27 -> 37.778682 | S30: =S21+S24+S27 -> 40.870661 | T30: =T21+T24+T27 -> 41.280373 | U30: =U21+U24+U27 -> 53.800624 | V30: =SUM(R30:U30) -> 173.73034 | W30: =W21+W24+W27 -> 41.41331 | X30: =X21+X24+X27 -> 43.841 | Y30: =Y21+Y24+Y27 -> 45.007061 | Z30: =Z21+Z24+Z27 -> 65.964073 | AA30: =SUM(W30:Z30) -> 196.22544 | AB30: =AB21+AB24+AB27 -> 58.586613 | AC30: =AC21+AC24+AC27 -> 58.298 | AD30: =AD21+AD24+AD27 -> 56.872656 | AE30: =AE21+AE24+AE27 -> 75.656 | AF30: =SUM(AB30:AE30) -> 249.41327 | AG30: =AG21+AG24+AG27 -> 63.79 | AH30: =AH21+AH24+AH27 -> 66.826231 | AI30: =AI21+AI24+AI27 -> 71.24605 | AJ30: =AJ21+AJ24+AJ27 -> 96.079555 | AK30: =SUM(AG30:AJ30) -> 297.94183 | AL30: =AL21+AL24+AL27 -> 353.14299 | AM30: =AM21+AM24+AM27 -> 416.63398 | AN30: =AN21+AN24+AN27 -> 487.75857 | AO30: =AO21+AO24+AO27 -> 567.20042 | AP30: =AP21+AP24+AP27 -> 655.69482 | AQ30: =AQ21+AQ24+AQ27 -> 754.03214 | AR30: =AR21+AR24+AR27 -> 863.06161 | AS30: =AS21+AS24+AS27 -> 983.69522 | AT30: =AT21+AT24+AT27 -> 1116.912 | AU30: x
B31: % margem ebitda | C31: =C30/C$16 -> 0.074945666 | D31: =D30/D$16 -> 0.045448726 | E31: =E30/E$16 -> 0.19493572 | F31: =F30/F$16 -> 0.27452624 | G31: =G30/G16 -> 0.19280556 | H31: =H30/H$16 -> 0.17249227 | I31: =I30/I$16 -> 0.21342925 | J31: =J30/J$16 -> 0.21664617 | K31: =K30/K$16 -> 0.28813729 | L31: =L30/L16 -> 0.23442211 | M31: =M30/M$16 -> 0.28768792 | N31: =N30/N$16 -> 0.21906643 | O31: =O30/O$16 -> 0.24784503 | P31: =P30/P$16 -> 0.26094112 | Q31: =Q30/Q16 -> 0.25335658 | R31: =R30/R$16 -> 0.26662913 | S31: =S30/S$16 -> 0.26236918 | T31: =T30/T$16 -> 0.25128406 | U31: =U30/U$16 -> 0.24240302 | V31: =V30/V16 -> 0.25410685 | W31: =W30/W$16 -> 0.25543116 | X31: =X30/X$16 -> 0.22833616 | Y31: =Y30/Y$16 -> 0.22026114 | Z31: =Z30/Z$16 -> 0.24136936 | AA31: =AA30/AA16 -> 0.23591623 | AB31: =AB30/AB$16 -> 0.27533114 | AC31: =AC30/AC$16 -> 0.24081027 | AD31: =AD30/AD$16 -> 0.21179335 | AE31: =AE30/AE$16 -> 0.23415226 | AF31: =AF30/AF16 -> 0.23832815 | AG31: =AG30/AG$16 -> 0.25398355 | AH31: =AH30/AH$16 -> 0.25648355 | AI31: =AI30/AI$16 -> 0.25898355 | AJ31: =AJ30/AJ$16 -> 0.26148355 | AK31: =AK30/AK16 -> 0.25812709 | AL31: =AL30/AL16 -> 0.26812709 | AM31: =AM30/AM16 -> 0.27812709 | AN31: =AN30/AN16 -> 0.28812709 | AO31: =AO30/AO16 -> 0.29812709 | AP31: =AP30/AP16 -> 0.30812709 | AQ31: =AQ30/AQ16 -> 0.31812709 | AR31: =AR30/AR16 -> 0.32812709 | ... AT31: =AT30/AT16 -> 0.34812709 | AU31: x
AU32: x
B33: (-) D&A | C33: =C509 -> -2.834 | D33: =D509 -> -2.828 | E33: =E509 -> -2.794 | F33: =F509 -> -2.619 | G33: =SUM(C33:F33) -> -11.075 | H33: =H509 -> -2.442 | I33: =I509 -> -2.427 | J33: =J509 -> -3.326 | K33: =K509 -> -3.315 | L33: =SUM(H33:K33) -> -11.51 | M33: =M509 -> -4 | N33: =N509 -> -4.308 | O33: =O509 -> -4.691 | P33: =P509 -> -5.545 | Q33: =SUM(M33:P33) -> -18.544 | R33: =R509 -> -5.817 | S33: =S509 -> -6.192 | T33: =T509 -> -6.375 | U33: =U509 -> -6.633 | V33: =SUM(R33:U33) -> -25.017 | W33: =W509 -> -7.098 | X33: =X509 -> -7.936 | Y33: =Y509 -> -8.253 | Z33: =Z509 -> -8.732 | AA33: =SUM(W33:Z33) -> -32.019 | AB33: =AB509 -> -8.266 | AC33: =AC509 -> -9.201 | AD33: =AD509 -> -9.42 | AE33: =AE509 -> -10.072 | AF33: =SUM(AB33:AE33) -> -36.959 | AG33: =AG509 -> -9.95 | AH33: =AH513 -> -11.255132 | AI33: =AI513 -> -11.558526 | AJ33: =AJ513 -> -12.362183 | AK33: =SUM(AG33:AJ33) -> -45.125841 | AL33: =AL513 -> -55.451571 | AM33: =AM513 -> -65.692383 | AN33: =AN513 -> -76.563593 | AO33: =AO513 -> -88.147027 | AP33: =AP513 -> -100.52105 | AQ33: =AQ513 -> -113.76236 | AR33: =AR513 -> -127.94735 | AS33: =AS513 -> -143.15321 | AT33: =AT513 -> -159.45883 | AU33: x
AU34: x
B35: EBIT | C35: =C30+C33 -> 1.373 | D35: =D30+D33 -> -1.763 | E35: =E30+E33 -> 10.124 | F35: =F30+F33 -> 30.731691 | G35: =SUM(C35:F35) -> 40.465691 | H35: =H30+H33 -> 8.548 | I35: =I30+I33 -> 17.729045 | J35: =J30+J33 -> 23.707328 | K35: =K30+K33 -> 40.383564 | L35: =SUM(H35:K35) -> 90.367937 | M35: =M30+M33 -> 28.371795 | N35: =N30+N33 -> 24.486748 | O35: =O30+O33 -> 29.548047 | P35: =P30+P33 -> 42.810522 | Q35: =SUM(M35:P35) -> 125.21711 | R35: =R30+R33 -> 31.961682 | S35: =S30+S33 -> 34.678661 | T35: =T30+T33 -> 34.905373 | U35: =U30+U33 -> 47.167624 | V35: =SUM(R35:U35) -> 148.71334 | W35: =W30+W33 -> 34.31531 | X35: =X30+X33 -> 35.905 | Y35: =Y30+Y33 -> 36.754061 | Z35: =Z30+Z33 -> 57.232073 | AA35: =SUM(W35:Z35) -> 164.20644 | AB35: =AB30+AB33 -> 50.320613 | AC35: =AC30+AC33 -> 49.097 | AD35: =AD30+AD33 -> 47.452656 | AE35: =AE30+AE33 -> 65.584 | AF35: =SUM(AB35:AE35) -> 212.45427 | AG35: =AG30+AG33 -> 53.84 | AH35: =AH30+AH33 -> 55.571099 | AI35: =AI30+AI33 -> 59.687524 | AJ35: =AJ30+AJ33 -> 83.717371 | AK35: =SUM(AG35:AJ35) -> 252.81599 | AL35: =AL30+AL33 -> 297.69142 | AM35: =AM30+AM33 -> 350.9416 | AN35: =AN30+AN33 -> 411.19498 | AO35: =AO30+AO33 -> 479.0534 | AP35: =AP30+AP33 -> 555.17376 | AQ35: =AQ30+AQ33 -> 640.26978 | AR35: =AR30+AR33 -> 735.11426 | AS35: =AS30+AS33 -> 840.54201 | AT35: =AT30+AT33 -> 957.45315 | AU35: x
B36: % margem ebit | C36: =C35/C$16 -> 0.024459329 | D36: =D35/D$16 -> -0.075235779 | E36: =E35/E$16 -> 0.15277359 | F36: =F35/F$16 -> 0.25296794 | G36: =G35/G16 -> 0.15137574 | H36: =H35/H$16 -> 0.13416414 | I36: =I35/I$16 -> 0.18773012 | J36: =J35/J$16 -> 0.18999147 | K36: =K35/K$16 -> 0.26627901 | L36: =L35/L16 -> 0.20793749 | M36: =M35/M$16 -> 0.25213995 | N36: =N35/N$16 -> 0.18629176 | O36: =O35/O$16 -> 0.21388845 | P36: =P35/P$16 -> 0.23101862 | Q36: =Q35/Q16 -> 0.22067567 | R36: =R35/R$16 -> 0.22557472 | S36: =S35/S$16 -> 0.22261964 | T36: =T35/T$16 -> 0.21247782 | U36: =U35/U$16 -> 0.21251751 | V36: =V35/V16 -> 0.21751571 | W36: =W35/W$16 -> 0.21165175 | X36: =X35/X$16 -> 0.18700326 | Y36: =Y35/Y$16 -> 0.17987159 | Z36: =Z35/Z$16 -> 0.20941807 | AA36: =AA35/AA16 -> 0.1974207 | AB36: =AB35/AB$16 -> 0.2364846 | AC36: =AC35/AC$16 -> 0.2028039 | AD36: =AD35/AD$16 -> 0.17671334 | AE36: =AE35/AE$16 -> 0.20297983 | AF36: =AF35/AF16 -> 0.20301178 | AG36: =AG35/AG$16 -> 0.21436705 | AH36: =AH35/AH$16 -> 0.2132856 | AI36: =AI35/AI$16 -> 0.21696763 | AJ36: =AJ35/AJ$16 -> 0.22783948 | AK36: =AK35/AK16 -> 0.21903154 | AL36: =AL35/AL16 -> 0.22602497 | AM36: =AM35/AM16 -> 0.23427366 | AN36: =AN35/AN16 -> 0.24289971 | AO36: =AO35/AO16 -> 0.251796 | AP36: =AP35/AP16 -> 0.26088978 | AQ36: =AQ35/AQ16 -> 0.27013061 | AR36: =AR35/AR16 -> 0.27948283 | ... AT36: =AT35/AT16 -> 0.29842583 | AU36: x
AU37: x
B38: (-) Resultado financeiro | C38: =C308 -> -1.127 | D38: =D308 -> -0.9 | E38: =E308 -> -0.717 | F38: =F308 -> -2.3635138 | G38: =SUM(C38:F38) -> -5.1075138 | H38: =H308 -> 0.011 | I38: =I308 -> -1.077 | J38: =J308 -> -0.84942961 | K38: =K308 -> 0.27859706 | L38: =SUM(H38:K38) -> -1.6368326 | M38: =M308 -> -1.2259987 | N38: =N308 -> -0.798 | O38: =O308 -> -1.1429935 | P38: =P308 -> -1.6297332 | Q38: =SUM(M38:P38) -> -4.7967253 | R38: =R308 -> -2.66 | S38: =S308 -> -2.881 | T38: =T308 -> -3.051 | U38: =U308 -> -3.1921326 | V38: =SUM(R38:U38) -> -11.784133 | W38: =W308 -> -3.534 | X38: =X308 -> -3.937 | Y38: =Y308 -> -5.329 | Z38: =Z308 -> -3.965731 | AA38: =SUM(W38:Z38) -> -16.765731 | AB38: =AB308 -> -7.685 | AC38: =AC308 -> -6.945 | AD38: =AD308 -> -8.5344265 | AE38: =AE308 -> -9.512 | AF38: =SUM(AB38:AE38) -> -32.676427 | AG38: =AG308 -> -10.438 | AH38: =AH308 -> -8.6196586 | AI38: =AI308 -> -9.2383245 | AJ38: =AJ308 -> -11.465266 | AK38: =SUM(AG38:AJ38) -> -39.761249 | AL38: =AL308 -> -46.131487 | AM38: =AM308 -> -52.682328 | AN38: =AN308 -> -57.280853 | AO38: =AO308 -> -61.873279 | AP38: =AP308 -> -66.429598 | AQ38: =AQ308 -> -70.915934 | AR38: =AR308 -> -75.294189 | AS38: =AS308 -> -79.521653 | AT38: =AT308 -> -83.550594 | AU38: x
AU39: x
B40: EBT | C40: =C35+C38 -> 0.246 | D40: =D35+D38 -> -2.663 | E40: =E35+E38 -> 9.407 | F40: =F35+F38 -> 28.368177 | G40: =SUM(C40:F40) -> 35.358177 | H40: =H35+H38 -> 8.559 | I40: =I35+I38 -> 16.652045 | J40: =J35+J38 -> 22.857899 | K40: =K35+K38 -> 40.662161 | L40: =SUM(H40:K40) -> 88.731105 | M40: =M35+M38 -> 27.145797 | N40: =N35+N38 -> 23.688748 | O40: =O35+O38 -> 28.405054 | P40: =P35+P38 -> 41.180789 | Q40: =SUM(M40:P40) -> 120.42039 | R40: =R35+R38 -> 29.301682 | S40: =S35+S38 -> 31.797661 | T40: =T35+T38 -> 31.854373 | U40: =U35+U38 -> 43.975491 | V40: =SUM(R40:U40) -> 136.92921 | W40: =W35+W38 -> 30.78131 | X40: =X35+X38 -> 31.968 | Y40: =Y35+Y38 -> 31.425061 | Z40: =Z35+Z38 -> 53.266342 | AA40: =SUM(W40:Z40) -> 147.44071 | AB40: =AB35+AB38 -> 42.635613 | AC40: =AC35+AC38 -> 42.152 | AD40: =AD35+AD38 -> 38.918229 | AE40: =AE35+AE38 -> 56.072 | AF40: =SUM(AB40:AE40) -> 179.77784 | AG40: =AG35+AG38 -> 43.402 | AH40: =AH35+AH38 -> 46.95144 | AI40: =AI35+AI38 -> 50.449199 | AJ40: =AJ35+AJ38 -> 72.252105 | AK40: =SUM(AG40:AJ40) -> 213.05474 | AL40: =AL35+AL38 -> 251.55993 | AM40: =AM35+AM38 -> 298.25927 | AN40: =AN35+AN38 -> 353.91412 | AO40: =AO35+AO38 -> 417.18012 | AP40: =AP35+AP38 -> 488.74417 | AQ40: =AQ35+AQ38 -> 569.35384 | AR40: =AR35+AR38 -> 659.82007 | AS40: =AS35+AS38 -> 761.02036 | AT40: =AT35+AT38 -> 873.90255 | AU40: x
B41: % margem ebt | C41: =C40/C$16 -> 0.0043823708 | D41: =D40/D$16 -> -0.11364315 | E41: =E40/E$16 -> 0.14195388 | F41: =F40/F$16 -> 0.23351267 | G41: =G40/G16 -> 0.13226934 | H41: =H40/H$16 -> 0.13433679 | I41: =I40/I$16 -> 0.17632594 | J41: =J40/J$16 -> 0.18318411 | K41: =K40/K$16 -> 0.26811601 | L41: =L40/L16 -> 0.20417112 | M41: =M40/M$16 -> 0.24124451 | N41: =N40/N$16 -> 0.18022069 | O41: =O40/O$16 -> 0.2056147 | P41: =P40/P$16 -> 0.22222408 | Q41: =Q40/Q16 -> 0.21222219 | R41: =R40/R$16 -> 0.20680134 | S41: =S40/S$16 -> 0.20412507 | T41: =T40/T$16 -> 0.19390562 | U41: =U40/U$16 -> 0.1981351 | V41: =V40/V16 -> 0.20027964 | W41: =W40/W$16 -> 0.18985456 | X41: =X40/X$16 -> 0.16649827 | Y41: =Y40/Y$16 -> 0.15379187 | Z41: =Z40/Z$16 -> 0.19490705 | AA41: =AA40/AA16 -> 0.17726374 | AB41: =AB40/AB$16 -> 0.20036851 | AC41: =AC40/AC$16 -> 0.17411634 | AD41: =AD40/AD$16 -> 0.1449312 | AE41: =AE40/AE$16 -> 0.17354057 | AF41: =AF40/AF16 -> 0.17178765 | AG41: =AG40/AG$16 -> 0.17280756 | AH41: =AH40/AH$16 -> 0.18020277 | AI41: =AI40/AI$16 -> 0.18338578 | AJ41: =AJ40/AJ$16 -> 0.19663639 | AK41: =AK40/AK16 -> 0.18458369 | AL41: =AL40/AL16 -> 0.19099921 | AM41: =AM40/AM16 -> 0.19910518 | AN41: =AN40/AN16 -> 0.20906295 | AO41: =AO40/AO16 -> 0.21927469 | AP41: =AP40/AP16 -> 0.22967288 | AQ41: =AQ40/AQ16 -> 0.24021109 | AR41: =AR40/AR16 -> 0.25085676 | ... AT41: =AT40/AT16 -> 0.27238418 | AU41: x
...
